Workbook

Sheet TỔNG QUAN
A1: BẢNG THEO DÕI TIẾN ĐỘ KHÓA HỌC
A2: Kho khóa học: D:\Sao lưu\Udemy\Khóa học — cập nhật từ cấu trúc thư mục hiện có
A4: TỔNG KHÓA | D4: TỔNG MODULE | G4: MODULE ĐÃ XONG | J4: TIẾN ĐỘ TOÀN KHO | M4: ĐIỂM TRUNG BÌNH
A5: =COUNTA(B12:B88) -> 77 | D5: =SUM(E12:E88) -> 992 | G5: =SUM(F12:F88) -> 0 | J5: =IFERROR(AVERAGE(G12:G88),0) -> 0 | M5: =IFERROR(AVERAGE(H12:H88),"")
A8: Cập nhật trực tiếp ở các sheet khóa học. Dùng bộ lọc ở bảng dưới để xem theo lĩnh vực, trạng thái hoặc tiến độ.
A10: DANH SÁCH KHÓA HỌC | L10: TỔNG HỢP THEO LĨNH VỰC
A11: Mã | B11: Cột1 | C11: Cột2 | D11: Cột3 | E11: Cột4 | F11: Cột5 | G11: Cột6 | H11: Cột7 | I11: Cột8 | J11: Cột9 | L11: Lĩnh vực
A12: C01 | B12: AI Agent 365 Ngày | C12: 01 - AI & Dữ liệu | D12: 01 - AI Engineering & LLM | E12: ='C01 AI Agent 365 Ngày'!$A$6 -> 8 | F12: ='C01 AI Agent 365 Ngày'!$C$6 -> 0 | G12: ='C01 AI Agent 365 Ngày'!$E$6 -> 0 | H12: ='C01 AI Agent 365 Ngày'!$G$6 | I12: =IF(E12=0,"Chưa có module",IF(F12=E12,"Đã hoàn thành",IF(F12=0,"Chưa bắt đầu","Đang học"))) -> Chưa bắt đầu | J12: C01 AI Agent 365 Ngày | L12: 01 - AI & Dữ liệu | M12: =COUNTIF($C$12:$C$88,L12) -> 18 | N12: =IFERROR(AVERAGEIF($C$12:$C$88,L12,$G$12:$G$88),0) -> 0
A13: C02 | B13: AI Engineer Roadmap Course | C13: 01 - AI & Dữ liệu | D13: 01 - AI Engineering & LLM | E13: ='C02 AI Engineer Roadmap Course'!$A$6 -> 1 | F13: ='C02 AI Engineer Roadmap Course'!$C$6 -> 0 | G13: ='C02 AI Engineer Roadmap Course'!$E$6 -> 0 | H13: ='C02 AI Engineer Roadmap Course'!$G$6 | I13: =IF(E13=0,"Chưa có module",IF(F13=E13,"Đã hoàn thành",IF(F13=0,"Chưa bắt đầu","Đang học"))) -> Chưa bắt đầu | J13: C02 AI Engineer Roadmap Course | L13: 02 - Lập trình & Phát triển phần mềm | M13: =COUNTIF($C$12:$C$88,L13) -> 12 | N13: =IFERROR(AVERAGEIF($C$12:$C$88,L13,$G$12:$G$88),0) -> 0
A14: C03 | B14: LangChain - Agentic AI Engineering with LangChain & LangGraph | C14: 01 - AI & Dữ liệu | D14: 01 - AI Engineering & LLM | E14: ='C03 LangChain - Agentic AI Engi'!$A$6 -> 28 | F14: ='C03 LangChain - Agentic AI Engi'!$C$6 -> 0 | G14: ='C03 LangChain - Agentic AI Engi'!$E$6 -> 0 | H14: ='C03 LangChain - Agentic AI Engi'!$G$6 | I14: =IF(E14=0,"Chưa có module",IF(F14=E14,"Đã hoàn thành",IF(F14=0,"Chưa bắt đầu","Đang học"))) -> Chưa bắt đầu | J14: C03 LangChain - Agentic AI Engi | L14: 03 - Hạ tầng, Mạng & An ninh | M14: =COUNTIF($C$12:$C$88,L14) -> 5 | N14: =IFERROR(AVERAGEIF($C$12:$C$88,L14,$G$12:$G$88),0) -> 0
A15: C04 | B15: Basic to Advanced: Retrieval-Augmented Generation — RAG | C15: 01 - AI & Dữ liệu | D15: 01 - AI Engineering & LLM | E15: ='C04 Basic to Advanced- Retrieva'!$A$6 -> 9 | F15: ='C04 Basic to Advanced- Retrieva'!$C$6 -> 0 | G15: ='C04 Basic to Advanced- Retrieva'!$E$6 -> 0 | H15: ='C04 Basic to Advanced- Retrieva'!$G$6 | I15: =IF(E15=0,"Chưa có module",IF(F15=E15,"Đã hoàn thành",IF(F15=0,"Chưa bắt đầu","Đang học"))) -> Chưa bắt đầu | J15: C04 Basic to Advanced- Retrieva | L15: 04 - Thiết kế & Sáng tạo số | M15: =COUNTIF($C$12:$C$88,L15) -> 15 | N15: =IFERROR(AVERAGEIF($C$12:$C$88,L15,$G$12:$G$88),0) -> 0
A16: C05 | B16: Ultimate RAG Bootcamp Using LangChain, LangGraph & LangSmith | C16: 01 - AI & Dữ liệu | D16: 01 - AI Engineering & LLM | E16: ='C05 Ultimate RAG Bootcamp Using'!$A$6 -> 29 | F16: ='C05 Ultimate RAG Bootcamp Using'!$C$6 -> 0 | G16: ='C05 Ultimate RAG Bootcamp Using'!$E$6 -> 0 | H16: ='C05 Ultimate RAG Bootcamp Using'!$G$6 | I16: =IF(E16=0,"Chưa có module",IF(F16=E16,"Đã hoàn thành",IF(F16=0,"Chưa bắt đầu","Đang học"))) -> Chưa bắt đầu | J16: C05 Ultimate RAG Bootcamp Using | L16: 05 - Phát triển game | M16: =COUNTIF($C$12:$C$88,L16) -> 9 | N16: =IFERROR(AVERAGEIF($C$12:$C$88,L16,$G$12:$G$88),0) -> 0
A17: C06 | B17: AI & Data Scientist Roadmap Course | C17: 01 - AI & Dữ liệu | D17: 02 - Data Science, Analytics & ML | E17: ='C06 AI & Data Scientist Roadmap'!$A$6 -> 1 | F17: ='C06 AI & Data Scientist Roadmap'!$C$6 -> 0 | G17: ='C06 AI & Data Scientist Roadmap'!$E$6 -> 0 | H17: ='C06 AI & Data Scientist Roadmap'!$G$6 | I17: =IF(E17=0,"Chưa có module",IF(F17=E17,"Đã hoàn thành",IF(F17=0,"Chưa bắt đầu","Đang học"))) -> Chưa bắt đầu | J17: C06 AI & Data Scientist Roadmap | L17: 06 - Ngôn ngữ | M17: =COUNTIF($C$12:$C$88,L17) -> 12 | N17: =IFERROR(AVERAGEIF($C$12:$C$88,L17,$G$12:$G$88),0) -> 0
A18: C07 | B18: bi-analyst-roadmap | C18: 01 - AI & Dữ liệu | D18: 02 - Data Science, Analytics & ML | E18: ='C07 bi-analyst-roadmap'!$A$6 -> 2 | F18: ='C07 bi-analyst-roadmap'!$C$6 -> 0 | G18: ='C07 bi-analyst-roadmap'!$E$6 -> 0 | H18: ='C07 bi-analyst-roadmap'!$G$6 | I18: =IF(E18=0,"Chưa có module",IF(F18=E18,"Đã hoàn thành",IF(F18=0,"Chưa bắt đầu","Đang học"))) -> Chưa bắt đầu | J18: C07 bi-analyst-roadmap | L18: 07 - Kinh doanh & Quản lý | M18: =COUNTIF($C$12:$C$88,L18) -> 4 | N18: =IFERROR(AVERAGEIF($C$12:$C$88,L18,$G$12:$G$88),0) -> 0
A19: C08 | B19: data-analyst-roadmap | C19: 01 - AI & Dữ liệu | D19: 02 - Data Science, Analytics & ML | E19: ='C08 data-analyst-roadmap'!$A$6 -> 1 | F19: ='C08 data-analyst-roadmap'!$C$6 -> 0 | G19: ='C08 data-analyst-roadmap'!$E$6 -> 0 | H19: ='C08 data-analyst-roadmap'!$G$6 | I19: =IF(E19=0,"Chưa có module",IF(F19=E19,"Đã hoàn thành",IF(F19=0,"Chưa bắt đầu","Đang học"))) -> Chưa bắt đầu | J19: C08 data-analyst-roadmap | L19: 08 - Sức khỏe & Đời sống | M19: =COUNTIF($C$12:$C$88,L19) -> 1 | N19: =IFERROR(AVERAGEIF($C$12:$C$88,L19,$G$12:$G$88),0) -> 0
A20: C09 | B20: data-engineer-roadmap | C20: 01 - AI & Dữ liệu | D20: 02 - Data Science, Analytics & ML | E20: ='C09 data-engineer-roadmap'!$A$6 -> 1 | F20: ='C09 data-engineer-roadmap'!$C$6 -> 0 | G20: ='C09 data-engineer-roadmap'!$E$6 -> 0 | H20: ='C09 data-engineer-roadmap'!$G$6 | I20: =IF(E20=0,"Chưa có module",IF(F20=E20,"Đã hoàn thành",IF(F20=0,"Chưa bắt đầu","Đang học"))) -> Chưa bắt đầu | J20: C09 data-engineer-roadmap | L20: 09 - Viết & Sáng tác | M20: =COUNTIF($C$12:$C$88,L20) -> 1 | N20: =IFERROR(AVERAGEIF($C$12:$C$88,L20,$G$12:$G$88),0) -> 0
A21: C10 | B21: Khóa Học Tính Toán Tiến Hóa (Evolutionary Computation) | C21: 01 - AI & Dữ liệu | D21: 02 - Data Science, Analytics & ML | E21: ='C10 Khóa Học Tính Toán Tiến Hóa'!$A$6 -> 10 | F21: ='C10 Khóa Học Tính Toán Tiến Hóa'!$C$6 -> 0 | G21: ='C10 Khóa Học Tính Toán Tiến Hóa'!$E$6 -> 0 | H21: ='C10 Khóa Học Tính Toán Tiến Hóa'!$G$6 | I21: =IF(E21=0,"Chưa có module",IF(F21=E21,"Đã hoàn thành",IF(F21=0,"Chưa bắt đầu","Đang học"))) -> Chưa bắt đầu | J21: C10 Khóa Học Tính Toán Tiến Hóa
A22: C11 | B22: machine-learning-roadmap | C22: 01 - AI & Dữ liệu | D22: 02 - Data Science, Analytics & ML | E22: ='C11 machine-learning-roadmap'!$A$6 -> 1 | F22: ='C11 machine-learning-roadmap'!$C$6 -> 0 | G22: ='C11 machine-learning-roadmap'!$E$6 -> 0 | H22: ='C11 machine-learning-roadmap'!$G$6 | I22: =IF(E22=0,"Chưa có module",IF(F22=E22,"Đã hoàn thành",IF(F22=0,"Chưa bắt đầu","Đang học"))) -> Chưa bắt đầu | J22: C11 machine-learning-roadmap
A23: C12 | B23: AI Coder: Complete Claude Code & Coding Agents Course | C23: 01 - AI & Dữ liệu | D23: 03 - AI hỗ trợ phát triển phần mềm | E23: ='C12 AI Coder- Complete Claude C'!$A$6 -> 16 | F23: ='C12 AI Coder- Complete Claude C'!$C$6 -> 0 | G23: ='C12 AI Coder- Complete Claude C'!$E$6 -> 0 | H23: ='C12 AI Coder- Complete Claude C'!$G$6 | I23: =IF(E23=0,"Chưa có module",IF(F23=E23,"Đã hoàn thành",IF(F23=0,"Chưa bắt đầu","Đang học"))) -> Chưa bắt đầu | J23: C12 AI Coder- Complete Claude C
A24: C13 | B24: claude-aiagents-cowork-masterclass | C24: 01 - AI & Dữ liệu | D24: 03 - AI hỗ trợ phát triển phần mềm | E24: ='C13 claude-aiagents-cowork-mast'!$A$6 -> 13 | F24: ='C13 claude-aiagents-cowork-mast'!$C$6 -> 0 | G24: ='C13 claude-aiagents-cowork-mast'!$E$6 -> 0 | H24: ='C13 claude-aiagents-cowork-mast'!$G$6 | I24: =IF(E24=0,"Chưa có module",IF(F24=E24,"Đã hoàn thành",IF(F24=0,"Chưa bắt đầu","Đang học"))) -> Chưa bắt đầu | J24: C13 claude-aiagents-cowork-mast
A25: C14 | B25: The Complete Claude Code & Claude Cowork Masterclass [2026] | C25: 01 - AI & Dữ liệu | D25: 03 - AI hỗ trợ phát triển phần mềm | E25: ='C14 The Complete Claude Code &'!$A$6 -> 13 | F25: ='C14 The Complete Claude Code &'!$C$6 -> 0 | G25: ='C14 The Complete Claude Code &'!$E$6 -> 0 | H25: ='C14 The Complete Claude Code &'!$G$6 | I25: =IF(E25=0,"Chưa có module",IF(F25=E25,"Đã hoàn thành",IF(F25=0,"Chưa bắt đầu","Đang học"))) -> Chưa bắt đầu | J25: C14 The Complete Claude Code &
A26: C15 | B26: Claude Code - The Practical Guide | C26: 01 - AI & Dữ liệu | D26: 03 - AI hỗ trợ phát triển phần mềm | E26: ='C15 Claude Code - The Practical'!$A$6 -> 3 | F26: ='C15 Claude Code - The Practical'!$C$6 -> 0 | G26: ='C15 Claude Code - The Practical'!$E$6 -> 0 | H26: ='C15 Claude Code - The Practical'!$G$6 | I26: =IF(E26=0,"Chưa có module",IF(F26=E26,"Đã hoàn thành",IF(F26=0,"Chưa bắt đầu","Đang học"))) -> Chưa bắt đầu | J26: C15 Claude Code - The Practical
A27: C16 | B27: khoa-hoc-vibe-coding | C27: 01 - AI & Dữ liệu | D27: 03 - AI hỗ trợ phát triển phần mềm | E27: ='C16 khoa-hoc-vibe-coding'!$A$6 -> 12 | F27: ='C16 khoa-hoc-vibe-coding'!$C$6 -> 0 | G27: ='C16 khoa-hoc-vibe-coding'!$E$6 -> 0 | H27: ='C16 khoa-hoc-vibe-coding'!$G$6 | I27: =IF(E27=0,"Chưa có module",IF(F27=E27,"Đã hoàn thành",IF(F27=0,"Chưa bắt đầu","Đang học"))) -> Chưa bắt đầu | J27: C16 khoa-hoc-vibe-coding
A28: C17 | B28: Khóa Học Vibe Coding Cơ Bản Cho Người Mới Bắt Đầu | C28: 01 - AI & Dữ liệu | D28: 03 - AI hỗ trợ phát triển phần mềm | E28: ='C17 Khóa Học Vibe Coding Cơ Bản'!$A$6 -> 6 | F28: ='C17 Khóa Học Vibe Coding Cơ Bản'!$C$6 -> 0 | G28: ='C17 Khóa Học Vibe Coding Cơ Bản'!$E$6 -> 0 | H28: ='C17 Khóa Học Vibe Coding Cơ Bản'!$G$6 | I28: =IF(E28=0,"Chưa có module",IF(F28=E28,"Đã hoàn thành",IF(F28=0,"Chưa bắt đầu","Đang học"))) -> Chưa bắt đầu | J28: C17 Khóa Học Vibe Coding Cơ Bản
A29: C18 | B29: Backend Developer Roadmap Workspace | C29: 02 - Lập trình & Phát triển phần mềm | D29: 01 - Web & Backend | E29: ='C18 Backend Developer Roadmap W'!$A$6 -> 2 | F29: ='C18 Backend Developer Roadmap W'!$C$6 -> 0 | G29: ='C18 Backend Developer Roadmap W'!$E$6 -> 0 | H29: ='C18 Backend Developer Roadmap W'!$G$6 | I29: =IF(E29=0,"Chưa có module",IF(F29=E29,"Đã hoàn thành",IF(F29=0,"Chưa bắt đầu","Đang học"))) -> Chưa bắt đầu | J29: C18 Backend Developer Roadmap W
A30: C19 | B30: frontend-developer-roadmap | C30: 02 - Lập trình & Phát triển phần mềm | D30: 01 - Web & Backend | E30: ='C19 frontend-developer-roadmap'!$A$6 -> 1 | F30: ='C19 frontend-developer-roadmap'!$C$6 -> 0 | G30: ='C19 frontend-developer-roadmap'!$E$6 -> 0 | H30: ='C19 frontend-developer-roadmap'!$G$6 | I30: =IF(E30=0,"Chưa có module",IF(F30=E30,"Đã hoàn thành",IF(F30=0,"Chưa bắt đầu","Đang học"))) -> Chưa bắt đầu | J30: C19 frontend-developer-roadmap
A31: C20 | B31: full-stack-developer-roadmap | C31: 02 - Lập trình & Phát triển phần mềm | D31: 01 - Web & Backend | E31: ='C20 full-stack-developer-roadma'!$A$6 -> 1 | F31: ='C20 full-stack-developer-roadma'!$C$6 -> 0 | G31: ='C20 full-stack-developer-roadma'!$E$6 -> 0 | H31: ='C20 full-stack-developer-roadma'!$G$6 | I31: =IF(E31=0,"Chưa có module",IF(F31=E31,"Đã hoàn thành",IF(F31=0,"Chưa bắt đầu","Đang học"))) -> Chưa bắt đầu | J31: C20 full-stack-developer-roadma
A32: C21 | B32: NodeJS - The Complete Guide | C32: 02 - Lập trình & Phát triển phần mềm | D32: 01 - Web & Backend | E32: ='C21 NodeJS - The Complete Guide'!$A$6 -> 36 | F32: ='C21 NodeJS - The Complete Guide'!$C$6 -> 0 | G32: ='C21 NodeJS - The Complete Guide'!$E$6 -> 0 | H32: ='C21 NodeJS - The Complete Guide'!$G$6 | I32: =IF(E32=0,"Chưa có module",IF(F32=E32,"Đã hoàn thành",IF(F32=0,"Chưa bắt đầu","Đang học"))) -> Chưa bắt đầu | J32: C21 NodeJS - The Complete Guide
A33: C22 | B33: postgresql-dba-roadmap | C33: 02 - Lập trình & Phát triển phần mềm | D33: 01 - Web & Backend | E33: ='C22 postgresql-dba-roadmap'!$A$6 -> 1 | F33: ='C22 postgresql-dba-roadmap'!$C$6 -> 0 | G33: ='C22 postgresql-dba-roadmap'!$E$6 -> 0 | H33: ='C22 postgresql-dba-roadmap'!$G$6 | I33: =IF(E33=0,"Chưa có module",IF(F33=E33,"Đã hoàn thành",IF(F33=0,"Chưa bắt đầu","Đang học"))) -> Chưa bắt đầu | J33: C22 postgresql-dba-roadmap
A34: C23 | B34: Android Developer Roadmap Course | C34: 02 - Lập trình & Phát triển phần mềm | D34: 02 - Mobile | E34: ='C23 Android Developer Roadmap C'!$A$6 -> 1 | F34: ='C23 Android Developer Roadmap C'!$C$6 -> 0 | G34: ='C23 Android Developer Roadmap C'!$E$6 -> 0 | H34: ='C23 Android Developer Roadmap C'!$G$6 | I34: =IF(E34=0,"Chưa có module",IF(F34=E34,"Đã hoàn thành",IF(F34=0,"Chưa bắt đầu","Đang học"))) -> Chưa bắt đầu | J34: C23 Android Developer Roadmap C
A35: C24 | B35: 3-in-1 Flutter AI Masterclass: 15 Apps with Cursor & Figma | C35: 02 - Lập trình & Phát triển phần mềm | D35: 02 - Mobile | E35: ='C24 3-in-1 Flutter AI Mastercla'!$A$6 -> 22 | F35: ='C24 3-in-1 Flutter AI Mastercla'!$C$6 -> 0 | G35: ='C24 3-in-1 Flutter AI Mastercla'!$E$6 -> 0 | H35: ='C24 3-in-1 Flutter AI Mastercla'!$G$6 | I35: =IF(E35=0,"Chưa có module",IF(F35=E35,"Đã hoàn thành",IF(F35=0,"Chưa bắt đầu","Đang học"))) -> Chưa bắt đầu | J35: C24 3-in-1 Flutter AI Mastercla
A36: C25 | B36: Flutter & Dart: The Complete Guide | C36: 02 - Lập trình & Phát triển phần mềm | D36: 02 - Mobile | E36: ='C25 Flutter & Dart- The Complet'!$A$6 -> 15 | F36: ='C25 Flutter & Dart- The Complet'!$C$6 -> 0 | G36: ='C25 Flutter & Dart- The Complet'!$E$6 -> 0 | H36: ='C25 Flutter & Dart- The Complet'!$G$6 | I36: =IF(E36=0,"Chưa có module",IF(F36=E36,"Đã hoàn thành",IF(F36=0,"Chưa bắt đầu","Đang học"))) -> Chưa bắt đầu | J36: C25 Flutter & Dart- The Complet
A37: C26 | B37: ios-roadmap | C37: 02 - Lập trình & Phát triển phần mềm | D37: 02 - Mobile | E37: ='C26 ios-roadmap'!$A$6 -> 1 | F37: ='C26 ios-roadmap'!$C$6 -> 0 | G37: ='C26 ios-roadmap'!$E$6 -> 0 | H37: ='C26 ios-roadmap'!$G$6 | I37: =IF(E37=0,"Chưa có module",IF(F37=E37,"Đã hoàn thành",IF(F37=0,"Chưa bắt đầu","Đang học"))) -> Chưa bắt đầu | J37: C26 ios-roadmap
A38: C27 | B38: Enterprise Integration Engineer Course | C38: 02 - Lập trình & Phát triển phần mềm | D38: 03 - Kiến trúc & Tích hợp | E38: ='C27 Enterprise Integration Engi'!$A$6 -> 7 | F38: ='C27 Enterprise Integration Engi'!$C$6 -> 0 | G38: ='C27 Enterprise Integration Engi'!$E$6 -> 0 | H38: ='C27 Enterprise Integration Engi'!$G$6 | I38: =IF(E38=0,"Chưa có module",IF(F38=E38,"Đã hoàn thành",IF(F38=0,"Chưa bắt đầu","Đang học"))) -> Chưa bắt đầu | J38: C27 Enterprise Integration Engi
A39: C28 | B39: software-architect-roadmap | C39: 02 - Lập trình & Phát triển phần mềm | D39: 03 - Kiến trúc & Tích hợp | E39: ='C28 software-architect-roadmap'!$A$6 -> 1 | F39: ='C28 software-architect-roadmap'!$C$6 -> 0 | G39: ='C28 software-architect-roadmap'!$E$6 -> 0 | H39: ='C28 software-architect-roadmap'!$G$6 | I39: =IF(E39=0,"Chưa có module",IF(F39=E39,"Đã hoàn thành",IF(F39=0,"Chưa bắt đầu","Đang học"))) -> Chưa bắt đầu | J39: C28 software-architect-roadmap
A40: C29 | B40: qa-roadmap | C40: 02 - Lập trình & Phát triển phần mềm | D40: 04 - Kiểm thử phần mềm | E40: ='C29 qa-roadmap'!$A$6 -> 1 | F40: ='C29 qa-roadmap'!$C$6 -> 0 | G40: ='C29 qa-roadmap'!$E$6 -> 0 | H40: ='C29 qa-roadmap'!$G$6 | I40: =IF(E40=0,"Chưa có module",IF(F40=E40,"Đã hoàn thành",IF(F40=0,"Chưa bắt đầu","Đang học"))) -> Chưa bắt đầu | J40: C29 qa-roadmap
A41: C30 | B41: Fundamentals of Backend Communications & Protocols | C41: 03 - Hạ tầng, Mạng & An ninh | D41: 01 - Mạng & Giao tiếp hệ thống | E41: ='C30 Fundamentals of Backend Com'!$A$6 -> 8 | F41: ='C30 Fundamentals of Backend Com'!$C$6 -> 0 | G41: ='C30 Fundamentals of Backend Com'!$E$6 -> 0 | H41: ='C30 Fundamentals of Backend Com'!$G$6 | I41: =IF(E41=0,"Chưa có module",IF(F41=E41,"Đã hoàn thành",IF(F41=0,"Chưa bắt đầu","Đang học"))) -> Chưa bắt đầu | J41: C30 Fundamentals of Backend Com
A42: C31 | B42: network-engineer-roadmap | C42: 03 - Hạ tầng, Mạng & An ninh | D42: 01 - Mạng & Giao tiếp hệ thống | E42: ='C31 network-engineer-roadmap'!$A$6 -> 2 | F42: ='C31 network-engineer-roadmap'!$C$6 -> 0 | G42: ='C31 network-engineer-roadmap'!$E$6 -> 0 | H42: ='C31 network-engineer-roadmap'!$G$6 | I42: =IF(E42=0,"Chưa có module",IF(F42=E42,"Đã hoàn thành",IF(F42=0,"Chưa bắt đầu","Đang học"))) -> Chưa bắt đầu | J42: C31 network-engineer-roadmap
A43: C32 | B43: Cyber Security Expert Roadmap 2026 | C43: 03 - Hạ tầng, Mạng & An ninh | D43: 02 - An ninh mạng & DevSecOps | E43: ='C32 Cyber Security Expert Roadm'!$A$6 -> 1 | F43: ='C32 Cyber Security Expert Roadm'!$C$6 -> 0 | G43: ='C32 Cyber Security Expert Roadm'!$E$6 -> 0 | H43: ='C32 Cyber Security Expert Roadm'!$G$6 | I43: =IF(E43=0,"Chưa có module",IF(F43=E43,"Đã hoàn thành",IF(F43=0,"Chưa bắt đầu","Đang học"))) -> Chưa bắt đầu | J43: C32 Cyber Security Expert Roadm
A44: C33 | B44: devsecops-roadmap | C44: 03 - Hạ tầng, Mạng & An ninh | D44: 02 - An ninh mạng & DevSecOps | E44: ='C33 devsecops-roadmap'!$A$6 -> 1 | F44: ='C33 devsecops-roadmap'!$C$6 -> 0 | G44: ='C33 devsecops-roadmap'!$E$6 -> 0 | H44: ='C33 devsecops-roadmap'!$G$6 | I44: =IF(E44=0,"Chưa có module",IF(F44=E44,"Đã hoàn thành",IF(F44=0,"Chưa bắt đầu","Đang học"))) -> Chưa bắt đầu | J44: C33 devsecops-roadmap
...

Sheet HƯỚNG DẪN
A1: HƯỚNG DẪN SỬ DỤNG
A3: Mục đích
A4: Workbook này theo dõi tiến độ theo khóa học và module. Các ô nền vàng là nơi nhập liệu; các ô KPI và Tổng quan tự tính bằng công thức.
A6: Cách cập nhật tiến độ
A7: 1 | B7: Mở sheet của khóa học cần học trong danh sách tab phía dưới.
A8: 2 | B8: Ở từng module, chọn Trạng thái, nhập Tiến độ (%) và Điểm /10; điền Ngày hoàn thành khi kết thúc.
A9: 3 | B9: Xem sheet TỔNG QUAN để biết tiến độ toàn bộ kho và tiến độ theo từng lĩnh vực.
A10: 4 | B10: Không sửa các ô KPI/công thức; chỉ sửa các ô nền vàng và cột Ghi chú.
A11: 5 | B11: Điểm dùng thang 0–10; Tiến độ dùng phần trăm 0%–100%.
A13: Quy ước trạng thái
A14: Trạng thái
A15: Chưa bắt đầu | B15: Chưa học module
A16: Đang học | B16: Đang học hoặc đã học một phần
A17: Đã hoàn thành | B17: Đã hoàn thành module
A18: Tạm dừng | B18: Tạm thời chưa học tiếp
A20: Thêm khóa học mới
A21: Khi thêm một thư mục khóa học mới vào kho, hãy tạo một sheet mới bằng cách sao chép MẪU_KHÓA_MỚI, đổi tên theo mã khóa và nhập các module. Khi bạn báo có khóa mới, mình sẽ tạo sheet tương ứng và cập nhật TỔNG QUAN.
A25: Lưu ý: file .xlsx không tự theo dõi thay đổi của thư mục Windows. Sheet MẪU_KHÓA_MỚI giúp thêm sheet mới thống nhất và không phá công thức.

Sheet C74 Tự học phát âm tiếng Anh
A1: THEO DÕI KHÓA HỌC — Tự học phát âm tiếng Anh
A2: Mã khóa | B2: C74 | C2: Lĩnh vực | D2: 06 - Ngôn ngữ | E2: Chuyên ngành | F2: 01 - Tiếng Anh
A3: Thư mục nguồn | B3: D:\Sao lưu\Udemy\Khóa học\06 - Ngôn ngữ\01 - Tiếng Anh\tu-hoc-phat-am-tieng-anh-markdown.zip
A5: TỔNG MODULE | C5: ĐÃ HOÀN THÀNH | E5: TIẾN ĐỘ TRUNG BÌNH | G5: ĐIỂM TRUNG BÌNH
A6: =COUNTA(B10:B16) -> 7 | C6: =COUNTIF(D10:D16,"Đã hoàn thành") -> 0 | E6: =IFERROR(AVERAGE(E10:E16),0) -> 0 | G6: =IFERROR(AVERAGE(F10:F16),"")
A8: Sao chép sheet này khi thêm khóa mới. Mỗi dòng là một module; nhập trạng thái, tiến độ, điểm và ngày hoàn thành.
A9: STT | B9: Module | C9: Số bài | D9: Trạng thái | E9: Tiến độ (%) | F9: Điểm /10 | G9: Ngày hoàn thành | H9: Ghi chú
A10: =1 -> 1 | B10: Module 01 — Nền tảng và nguyên âm đơn | C10: =4 -> 4 | D10: Chưa bắt đầu | E10: =0 -> 0
A11: =2 -> 2 | B11: Module 02 — Nguyên âm đôi và tổng kết nguyên âm | C11: =4 -> 4 | D11: Chưa bắt đầu | E11: =0 -> 0
A12: =3 -> 3 | B12: Module 03 — Hệ thống phụ âm tiếng Anh | C12: =7 -> 7 | D12: Chưa bắt đầu | E12: =0 -> 0
A13: =4 -> 4 | B13: Module 04 — Biến thể và tổ hợp phụ âm | C13: =3 -> 3 | D13: Chưa bắt đầu | E13: =0 -> 0
A14: =5 -> 5 | B14: Module 05 — Nói tự nhiên: nối âm, trọng âm và ngữ điệu | C14: =5 -> 5 | D14: Chưa bắt đầu | E14: =0 -> 0
A15: =6 -> 6 | B15: Module 06 — Luyện tập tổng hợp | C15: =8 -> 8 | D15: Chưa bắt đầu | E15: =0 -> 0
A16: =7 -> 7 | B16: Module 07 — So sánh giọng Anh–Anh và Anh–Mỹ | C16: =1 -> 1 | D16: Chưa bắt đầu | E16: =0 -> 0
A17: 8 | D17: Chưa bắt đầu | E17: 0
A18: 9 | D18: Chưa bắt đầu | E18: 0
A19: 10 | D19: Chưa bắt đầu | E19: 0
A20: 11 | D20: Chưa bắt đầu | E20: 0
A21: 12 | D21: Chưa bắt đầu | E21: 0
A22: 13 | D22: Chưa bắt đầu | E22: 0
A23: 14 | D23: Chưa bắt đầu | E23: 0
A24: 15 | D24: Chưa bắt đầu | E24: 0
A25: 16 | D25: Chưa bắt đầu | E25: 0
A26: 17 | D26: Chưa bắt đầu | E26: 0
A27: 18 | D27: Chưa bắt đầu | E27: 0
A28: 19 | D28: Chưa bắt đầu | E28: 0
... A209: 200 | D209: Chưa bắt đầu | E209: 0

Sheet MẪU_KHÓA_MỚI
A1: MẪU THEO DÕI KHÓA MỚI
A2: Mã khóa | B2: Cxx | C2: Lĩnh vực | E2: Chuyên ngành
A3: Thư mục nguồn | B3: Dán đường dẫn thư mục khóa học tại đây
A5: TỔNG MODULE | C5: ĐÃ HOÀN THÀNH | E5: TIẾN ĐỘ TRUNG BÌNH | G5: ĐIỂM TRUNG BÌNH
A6: =COUNTA(B10:B209) -> 0 | C6: =COUNTIF(D10:D209,"Đã hoàn thành") -> 0 | E6: =IFERROR(AVERAGE(E10:E209),0) -> 0 | G6: =IFERROR(AVERAGE(F10:F209),"")
A8: Sao chép sheet này khi thêm khóa mới. Mỗi dòng là một module; nhập trạng thái, tiến độ, điểm và ngày hoàn thành.
A9: STT | B9: Module | C9: Số bài | D9: Trạng thái | E9: Tiến độ (%) | F9: Điểm /10 | G9: Ngày hoàn thành | H9: Ghi chú
A10: 1 | D10: Chưa bắt đầu | E10: 0
A11: 2 | D11: Chưa bắt đầu | E11: 0
A12: 3 | D12: Chưa bắt đầu | E12: 0
A13: 4 | D13: Chưa bắt đầu | E13: 0
A14: 5 | D14: Chưa bắt đầu | E14: 0
A15: 6 | D15: Chưa bắt đầu | E15: 0
A16: 7 | D16: Chưa bắt đầu | E16: 0
A17: 8 | D17: Chưa bắt đầu | E17: 0
A18: 9 | D18: Chưa bắt đầu | E18: 0
A19: 10 | D19: Chưa bắt đầu | E19: 0
A20: 11 | D20: Chưa bắt đầu | E20: 0
A21: 12 | D21: Chưa bắt đầu | E21: 0
... A209: 200 | D209: Chưa bắt đầu | E209: 0

Sheet C73 Creative Writing- How to Wr
A1: THEO DÕI KHÓA HỌC — Creative Writing: How to Write a Novel - The Full Course
A2: Mã khóa | B2: C73 | C2: Lĩnh vực | D2: 09 - Viết & Sáng tác | E2: Chuyên ngành | F2: 01 - Viết tiểu thuyết
A3: Thư mục nguồn | B3: D:\Sao lưu\Udemy\Khóa học\09 - Viết & Sáng tác\01 - Viết tiểu thuyết\creative-writing-how-to-write-a-novel
A5: TỔNG MODULE | C5: ĐÃ HOÀN THÀNH | E5: TIẾN ĐỘ TRUNG BÌNH | G5: ĐIỂM TRUNG BÌNH
A6: =COUNTA(B10:B13) -> 4 | C6: =COUNTIF(D10:D13,"Đã hoàn thành") -> 0 | E6: =IFERROR(AVERAGE(E10:E13),0) -> 0 | G6: =IFERROR(AVERAGE(F10:F13),"")
A8: Nhập Trạng thái, Tiến độ và Điểm ở các ô nền vàng. Tiến độ nhập từ 0% đến 100%; điểm từ 0 đến 10.
A9: STT | B9: Module | C9: Số bài | D9: Trạng thái | E9: Tiến độ (%) | F9: Điểm /10 | G9: Ngày hoàn thành | H9: Ghi chú
A10: 1 | B10: 01 - The Character | C10: 31 | D10: Chưa bắt đầu | E10: 0
A11: 2 | B11: 02 - The 3 Act Narrative Structure | C11: 20 | D11: Chưa bắt đầu | E11: 0
A12: 3 | B12: 03 - Show, Don't Tell | C12: 14 | D12: Chưa bắt đầu | E12: 0
A13: 4 | B13: 04 - Dialogue | C13: 12 | D13: Chưa bắt đầu | E13: 0

Sheet C72 nutrition-masterclass-build
A1: THEO DÕI KHÓA HỌC — nutrition-masterclass-build-your-perfect-diet-meal-plan
A2: Mã khóa | B2: C72 | C2: Lĩnh vực | D2: 08 - Sức khỏe & Đời sống | E2: Chuyên ngành | F2: 01 - Dinh dưỡng
A3: Thư mục nguồn | B3: D:\Sao lưu\Udemy\Khóa học\08 - Sức khỏe & Đời sống\01 - Dinh dưỡng\nutrition-masterclass-build-your-perfect-diet-meal-plan
A5: TỔNG MODULE | C5: ĐÃ HOÀN THÀNH | E5: TIẾN ĐỘ TRUNG BÌNH | G5: ĐIỂM TRUNG BÌNH
A6: =COUNTA(B10:B19) -> 10 | C6: =COUNTIF(D10:D19,"Đã hoàn thành") -> 0 | E6: =IFERROR(AVERAGE(E10:E19),0) -> 0 | G6: =IFERROR(AVERAGE(F10:F19),"")
A8: Nhập Trạng thái, Tiến độ và Điểm ở các ô nền vàng. Tiến độ nhập từ 0% đến 100%; điểm từ 0 đến 10.
A9: STT | B9: Module | C9: Số bài | D9: Trạng thái | E9: Tiến độ (%) | F9: Điểm /10 | G9: Ngày hoàn thành | H9: Ghi chú
A10: 1 | B10: 01 - Introduction | C10: 3 | D10: Chưa bắt đầu | E10: 0
A11: 2 | B11: 02 - Meal Planning Basics | C11: 21 | D11: Chưa bắt đầu | E11: 0
A12: 3 | B12: 03 - Supplements | C12: 7 | D12: Chưa bắt đầu | E12: 0
A13: 4 | B13: 04 - Setting Up Your Diet | C13: 13 | D13: Chưa bắt đầu | E13: 0
A14: 5 | B14: 05 - Adjusting Your Diet for Weight Loss and Muscle Gains | C14: 7 | D14: Chưa bắt đầu | E14: 0
A15: 6 | B15: 06 - Healthy Dieting | C15: 9 | D15: Chưa bắt đầu | E15: 0
A16: 7 | B16: 07 - Common Dieting Trends Explained | C16: 7 | D16: Chưa bắt đầu | E16: 0
A17: 8 | B17: 08 - Micronutrients | C17: 16 | D17: Chưa bắt đầu | E17: 0
A18: 9 | B18: 09 - More Dieting Tips and Strategies | C18: 7 | D18: Chưa bắt đầu | E18: 0
A19: 10 | B19: 10 - Bonus Lessons on Muscle Growth | C19: 4 | D19: Chưa bắt đầu | E19: 0

Sheet C71 technical-writer-roadmap
A1: THEO DÕI KHÓA HỌC — technical-writer-roadmap
A2: Mã khóa | B2: C71 | C2: Lĩnh vực | D2: 07 - Kinh doanh & Quản lý | E2: Chuyên ngành | F2: 02 - Developer Relations & Technical Writing
A3: Thư mục nguồn | B3: D:\Sao lưu\Udemy\Khóa học\07 - Kinh doanh & Quản lý\02 - Developer Relations & Technical Writing\technical-writer-roadmap
A5: TỔNG MODULE | C5: ĐÃ HOÀN THÀNH | E5: TIẾN ĐỘ TRUNG BÌNH | G5: ĐIỂM TRUNG BÌNH
A6: =COUNTA(B10:B10) -> 1 | C6: =COUNTIF(D10:D10,"Đã hoàn thành") -> 0 | E6: =IFERROR(AVERAGE(E10:E10),0) -> 0 | G6: =IFERROR(AVERAGE(F10:F10),"")
A8: Nhập Trạng thái, Tiến độ và Điểm ở các ô nền vàng. Tiến độ nhập từ 0% đến 100%; điểm từ 0 đến 10.
A9: STT | B9: Module | C9: Số bài | D9: Trạng thái | E9: Tiến độ (%) | F9: Điểm /10 | G9: Ngày hoàn thành | H9: Ghi chú
A10: 1 | B10: 00 - Roadmap.sh Technical Writer Official | C10: 59 | D10: Chưa bắt đầu | E10: 0

Sheet C70 devrel-roadmap
A1: THEO DÕI KHÓA HỌC — devrel-roadmap
A2: Mã khóa | B2: C70 | C2: Lĩnh vực | D2: 07 - Kinh doanh & Quản lý | E2: Chuyên ngành | F2: 02 - Developer Relations & Technical Writing
A3: Thư mục nguồn | B3: D:\Sao lưu\Udemy\Khóa học\07 - Kinh doanh & Quản lý\02 - Developer Relations & Technical Writing\devrel-roadmap
A5: TỔNG MODULE | C5: ĐÃ HOÀN THÀNH | E5: TIẾN ĐỘ TRUNG BÌNH | G5: ĐIỂM TRUNG BÌNH
A6: =COUNTA(B10:B11) -> 2 | C6: =COUNTIF(D10:D11,"Đã hoàn thành") -> 0 | E6: =IFERROR(AVERAGE(E10:E11),0) -> 0 | G6: =IFERROR(AVERAGE(F10:F11),"")
A8: Nhập Trạng thái, Tiến độ và Điểm ở các ô nền vàng. Tiến độ nhập từ 0% đến 100%; điểm từ 0 đến 10.
A9: STT | B9: Module | C9: Số bài | D9: Trạng thái | E9: Tiến độ (%) | F9: Điểm /10 | G9: Ngày hoàn thành | H9: Ghi chú
A10: 1 | B10: 00 - Roadmap.sh Developer Relations Official | C10: 33 | D10: Chưa bắt đầu | E10: 0
A11: 2 | B11: 99 - Portfolio Capstone Projects | C11: 5 | D11: Chưa bắt đầu | E11: 0

Sheet C69 product-manager-roadmap
A1: THEO DÕI KHÓA HỌC — product-manager-roadmap
A2: Mã khóa | B2: C69 | C2: Lĩnh vực | D2: 07 - Kinh doanh & Quản lý | E2: Chuyên ngành | F2: 01 - Product & Engineering Management
A3: Thư mục nguồn | B3: D:\Sao lưu\Udemy\Khóa học\07 - Kinh doanh & Quản lý\01 - Product & Engineering Management\product-manager-roadmap
A5: TỔNG MODULE | C5: ĐÃ HOÀN THÀNH | E5: TIẾN ĐỘ TRUNG BÌNH | G5: ĐIỂM TRUNG BÌNH
A6: =COUNTA(B10:B11) -> 2 | C6: =COUNTIF(D10:D11,"Đã hoàn thành") -> 0 | E6: =IFERROR(AVERAGE(E10:E11),0) -> 0 | G6: =IFERROR(AVERAGE(F10:F11),"")
A8: Nhập Trạng thái, Tiến độ và Điểm ở các ô nền vàng. Tiến độ nhập từ 0% đến 100%; điểm từ 0 đến 10.
A9: STT | B9: Module | C9: Số bài | D9: Trạng thái | E9: Tiến độ (%) | F9: Điểm /10 | G9: Ngày hoàn thành | H9: Ghi chú
A10: 1 | B10: 00 - Roadmap.sh Product Manager Official | C10: 148 | D10: Chưa bắt đầu | E10: 0
A11: 2 | B11: 99 - Portfolio Capstone Projects | C11: 5 | D11: Chưa bắt đầu | E11: 0

Sheet C68 engineering-manager-roadmap
A1: THEO DÕI KHÓA HỌC — engineering-manager-roadmap
A2: Mã khóa | B2: C68 | C2: Lĩnh vực | D2: 07 - Kinh doanh & Quản lý | E2: Chuyên ngành | F2: 01 - Product & Engineering Management
A3: Thư mục nguồn | B3: D:\Sao lưu\Udemy\Khóa học\07 - Kinh doanh & Quản lý\01 - Product & Engineering Management\engineering-manager-roadmap
A5: TỔNG MODULE | C5: ĐÃ HOÀN THÀNH | E5: TIẾN ĐỘ TRUNG BÌNH | G5: ĐIỂM TRUNG BÌNH
A6: =COUNTA(B10:B10) -> 1 | C6: =COUNTIF(D10:D10,"Đã hoàn thành") -> 0 | E6: =IFERROR(AVERAGE(E10:E10),0) -> 0 | G6: =IFERROR(AVERAGE(F10:F10),"")
A8: Nhập Trạng thái, Tiến độ và Điểm ở các ô nền vàng. Tiến độ nhập từ 0% đến 100%; điểm từ 0 đến 10.
A9: STT | B9: Module | C9: Số bài | D9: Trạng thái | E9: Tiến độ (%) | F9: Điểm /10 | G9: Ngày hoàn thành | H9: Ghi chú
A10: 1 | B10: 00 - Roadmap.sh Engineering Manager Official | C10: 98 | D10: Chưa bắt đầu | E10: 0

Sheet C67 Khóa học Tiếng Hàn toàn diệ
A1: THEO DÕI KHÓA HỌC — Khóa học Tiếng Hàn toàn diện cho người mới bắt đầu
A2: Mã khóa | B2: C67 | C2: Lĩnh vực | D2: 06 - Ngôn ngữ | E2: Chuyên ngành | F2: 06 - Tiếng Hàn
A3: Thư mục nguồn | B3: D:\Sao lưu\Udemy\Khóa học\06 - Ngôn ngữ\06 - Tiếng Hàn\complete-korean-course-for-beginners
A5: TỔNG MODULE | C5: ĐÃ HOÀN THÀNH | E5: TIẾN ĐỘ TRUNG BÌNH | G5: ĐIỂM TRUNG BÌNH
A6: =COUNTA(B10:B91) -> 82 | C6: =COUNTIF(D10:D91,"Đã hoàn thành") -> 0 | E6: =IFERROR(AVERAGE(E10:E91),0) -> 0 | G6: =IFERROR(AVERAGE(F10:F91),"")
A8: Nhập Trạng thái, Tiến độ và Điểm ở các ô nền vàng. Tiến độ nhập từ 0% đến 100%; điểm từ 0 đến 10.
A9: STT | B9: Module | C9: Số bài | D9: Trạng thái | E9: Tiến độ (%) | F9: Điểm /10 | G9: Ngày hoàn thành | H9: Ghi chú
A10: 1 | B10: 01 - Giới thiệu | C10: 4 | D10: Chưa bắt đầu | E10: 0
A11: 2 | B11: 02 - Phụ âm | C11: 10 | D11: Chưa bắt đầu | E11: 0
A12: 3 | B12: 03 - Nguyên âm | C12: 9 | D12: Chưa bắt đầu | E12: 0
A13: 4 | B13: 04 - Phụ âm căng, Nguyên âm đôi W và Tổ hợp CVC | C13: 19 | D13: Chưa bắt đầu | E13: 0
A14: 5 | B14: 05 - Cấu trúc Câu tiếng Hàn | C14: 11 | D14: Chưa bắt đầu | E14: 0
A15: 6 | B15: 06 - Các cụm từ tiếng Hàn cơ bản | C15: 12 | D15: Chưa bắt đầu | E15: 0
A16: 7 | B16: 07 - Tiếng Hàn Cho Người Mới Bắt Đầu Tuyệt Đối 2 | C16: 2 | D16: Chưa bắt đầu | E16: 0
A17: 8 | B17: 08 - Số đếm tiếng Hàn | C17: 7 | D17: Chưa bắt đầu | E17: 0
A18: 9 | B18: 09 - Thời gian & Ngày tháng | C18: 6 | D18: Chưa bắt đầu | E18: 0
A19: 10 | B19: 10 - Đại từ | C19: 4 | D19: Chưa bắt đầu | E19: 0
A20: 11 | B20: 11 - Cấu trúc Câu - Thì Hiện tại | C20: 10 | D20: Chưa bắt đầu | E20: 0
A21: 12 | B21: 12 - Động từ bất quy tắc | C21: 7 | D21: Chưa bắt đầu | E21: 0
... A91: 82 | B91: 82 - Bài 11 Sắp xếp kế hoạch | C91: 8 | D91: Chưa bắt đầu | E91: 0

Sheet C66 Tiếng Đức giao tiếp từ A1 đ
A1: THEO DÕI KHÓA HỌC — Tiếng Đức giao tiếp từ A1 đến B1
A2: Mã khóa | B2: C66 | C2: Lĩnh vực | D2: 06 - Ngôn ngữ | E2: Chuyên ngành | F2: 05 - Tiếng Đức
A3: Thư mục nguồn | B3: D:\Sao lưu\Udemy\Khóa học\06 - Ngôn ngữ\05 - Tiếng Đức\complete-german-course-speaking
A5: TỔNG MODULE | C5: ĐÃ HOÀN THÀNH | E5: TIẾN ĐỘ TRUNG BÌNH | G5: ĐIỂM TRUNG BÌNH
A6: =COUNTA(B10:B330) -> 321 | C6: =COUNTIF(D10:D330,"Đã hoàn thành") -> 0 | E6: =IFERROR(AVERAGE(E10:E330),0) -> 0 | G6: =IFERROR(AVERAGE(F10:F330),"")
A8: Nhập Trạng thái, Tiến độ và Điểm ở các ô nền vàng. Tiến độ nhập từ 0% đến 100%; điểm từ 0 đến 10.
A9: STT | B9: Module | C9: Số bài | D9: Trạng thái | E9: Tiến độ (%) | F9: Điểm /10 | G9: Ngày hoàn thành | H9: Ghi chú
A10: 1 | B10: Introduction | C10: 0 | D10: Chưa bắt đầu | E10: 0
A11: 2 | B11: A1 Unit 1 - Getting started | C11: 0 | D11: Chưa bắt đầu | E11: 0
A12: 3 | B12: A1 Unit 2 - Introducing yourself | C12: 0 | D12: Chưa bắt đầu | E12: 0
A13: 4 | B13: A1 Unit 3 - Talking about family and friends | C13: 0 | D13: Chưa bắt đầu | E13: 0
A14: 5 | B14: A1 Unit 4 - Talking about home | C14: 0 | D14: Chưa bắt đầu | E14: 0
A15: 6 | B15: A1 Unit 5 - Talking about routines | C15: 0 | D15: Chưa bắt đầu | E15: 0
A16: 7 | B16: A1 Unit 6 - Talking about work | C16: 0 | D16: Chưa bắt đầu | E16: 0
A17: 8 | B17: A1 Unit 7 - Talking about likes & dislikes | C17: 0 | D17: Chưa bắt đầu | E17: 0
A18: 9 | B18: A1 Unit 8 - Talking about free time activities | C18: 0 | D18: Chưa bắt đầu | E18: 0
A19: 10 | B19: A1 Unit 9 - Talking about your town or village | C19: 0 | D19: Chưa bắt đầu | E19: 0
A20: 11 | B20: A1 Unit 10 - Talking about the weather | C20: 0 | D20: Chưa bắt đầu | E20: 0
A21: 12 | B21: A1 Unit 11 - Talking about transport | C21: 0 | D21: Chưa bắt đầu | E21: 0
... A330: 321 | B330: Quiz và nhiệm vụ đầu ra. | C330: 0 | D330: Chưa bắt đầu | E330: 0

Sheet C65 Complete French Course — Kh
A1: THEO DÕI KHÓA HỌC — Complete French Course — Khóa học Markdown
A2: Mã khóa | B2: C65 | C2: Lĩnh vực | D2: 06 - Ngôn ngữ | E2: Chuyên ngành | F2: 04 - Tiếng Pháp
A3: Thư mục nguồn | B3: D:\Sao lưu\Udemy\Khóa học\06 - Ngôn ngữ\04 - Tiếng Pháp\complete-french-course
A5: TỔNG MODULE | C5: ĐÃ HOÀN THÀNH | E5: TIẾN ĐỘ TRUNG BÌNH | G5: ĐIỂM TRUNG BÌNH
A6: =COUNTA(B10:B16) -> 7 | C6: =COUNTIF(D10:D16,"Đã hoàn thành") -> 0 | E6: =IFERROR(AVERAGE(E10:E16),0) -> 0 | G6: =IFERROR(AVERAGE(F10:F16),"")
A8: Nhập Trạng thái, Tiến độ và Điểm ở các ô nền vàng. Tiến độ nhập từ 0% đến 100%; điểm từ 0 đến 10.
A9: STT | B9: Module | C9: Số bài | D9: Trạng thái | E9: Tiến độ (%) | F9: Điểm /10 | G9: Ngày hoàn thành | H9: Ghi chú
A10: 1 | B10: 01 - Beginner Course Chapter 1 | C10: 64 | D10: Chưa bắt đầu | E10: 0
A11: 2 | B11: 02 - Beginner Course Chapter 2 | C11: 20 | D11: Chưa bắt đầu | E11: 0
A12: 3 | B12: 03 - Beginner Course Chapter 3 | C12: 40 | D12: Chưa bắt đầu | E12: 0
A13: 4 | B13: 04 - Intermediate Course Chapter 1 | C13: 44 | D13: Chưa bắt đầu | E13: 0
A14: 5 | B14: 05 - 500 Most Useful French Words | C14: 4 | D14: Chưa bắt đầu | E14: 0
A15: 6 | B15: 06 - 500 Most Useful French Phrases | C15: 5 | D15: Chưa bắt đầu | E15: 0
A16: 7 | B16: 07 - Bonus Learn French with Music | C16: 14 | D16: Chưa bắt đầu | E16: 0

Sheet C64 Learn Japanese for Beginner
A1: THEO DÕI KHÓA HỌC — Learn Japanese for Beginners — Khóa học Markdown
A2: Mã khóa | B2: C64 | C2: Lĩnh vực | D2: 06 - Ngôn ngữ | E2: Chuyên ngành | F2: 03 - Tiếng Nhật
A3: Thư mục nguồn | B3: D:\Sao lưu\Udemy\Khóa học\06 - Ngôn ngữ\03 - Tiếng Nhật\learn-japanese-for-beginners-course
A5: TỔNG MODULE | C5: ĐÃ HOÀN THÀNH | E5: TIẾN ĐỘ TRUNG BÌNH | G5: ĐIỂM TRUNG BÌNH
A6: =COUNTA(B10:B24) -> 15 | C6: =COUNTIF(D10:D24,"Đã hoàn thành") -> 0 | E6: =IFERROR(AVERAGE(E10:E24),0) -> 0 | G6: =IFERROR(AVERAGE(F10:F24),"")
A8: Nhập Trạng thái, Tiến độ và Điểm ở các ô nền vàng. Tiến độ nhập từ 0% đến 100%; điểm từ 0 đến 10.
A9: STT | B9: Module | C9: Số bài | D9: Trạng thái | E9: Tiến độ (%) | F9: Điểm /10 | G9: Ngày hoàn thành | H9: Ghi chú
A10: 1 | B10: 01 - Introduction to Japanese | C10: 5 | D10: Chưa bắt đầu | E10: 0
A11: 2 | B11: 02 - Hiragana | C11: 20 | D11: Chưa bắt đầu | E11: 0
A12: 3 | B12: 03 - Katakana | C12: 20 | D12: Chưa bắt đầu | E12: 0
A13: 4 | B13: 04 - Pronunciation Basics | C13: 5 | D13: Chưa bắt đầu | E13: 0
A14: 5 | B14: 05 - Pronunciation Sound Changes and Pitch | C14: 5 | D14: Chưa bắt đầu | E14: 0
A15: 6 | B15: 06 - Self-Introduction, Greetings, and Manners | C15: 15 | D15: Chưa bắt đầu | E15: 0
A16: 7 | B16: 07 - Numbers and Counters | C16: 14 | D16: Chưa bắt đầu | E16: 0
A17: 8 | B17: 08 - Time, Dates, and Sentence Patterns | C17: 8 | D17: Chưa bắt đầu | E17: 0
A18: 9 | B18: 09 - Useful Everyday Questions | C18: 12 | D18: Chưa bắt đầu | E18: 0
A19: 10 | B19: 10 - Listening - Everyday Places and Services | C19: 12 | D19: Chưa bắt đầu | E19: 0
A20: 11 | B20: 11 - Listening - Daily Life and Plans | C20: 14 | D20: Chưa bắt đầu | E20: 0
A21: 12 | B21: 12 - Listening - Personal Topics and Shopping | C21: 14 | D21: Chưa bắt đầu | E21: 0
... A24: 15 | B24: 15 - Listening - Home, Time, and Travel | C24: 8 | D24: Chưa bắt đầu | E24: 0

Sheet C63 Mandarin Mastery Path — Tiế
A1: THEO DÕI KHÓA HỌC — Mandarin Mastery Path — Tiếng Trung từ Nền tảng đến HSK 3
A2: Mã khóa | B2: C63 | C2: Lĩnh vực | D2: 06 - Ngôn ngữ | E2: Chuyên ngành | F2: 02 - Tiếng Trung
A3: Thư mục nguồn | B3: D:\Sao lưu\Udemy\Khóa học\06 - Ngôn ngữ\02 - Tiếng Trung\mandarin-mastery-path
A5: TỔNG MODULE | C5: ĐÃ HOÀN THÀNH | E5: TIẾN ĐỘ TRUNG BÌNH | G5: ĐIỂM TRUNG BÌNH
A6: =COUNTA(B10:B65) -> 56 | C6: =COUNTIF(D10:D65,"Đã hoàn thành") -> 0 | E6: =IFERROR(AVERAGE(E10:E65),0) -> 0 | G6: =IFERROR(AVERAGE(F10:F65),"")
A8: Nhập Trạng thái, Tiến độ và Điểm ở các ô nền vàng. Tiến độ nhập từ 0% đến 100%; điểm từ 0 đến 10.
A9: STT | B9: Module | C9: Số bài | D9: Trạng thái | E9: Tiến độ (%) | F9: Điểm /10 | G9: Ngày hoàn thành | H9: Ghi chú
A10: 1 | B10: module-01-khoi-dong-hanh-trinh | C10: 2 | D10: Chưa bắt đầu | E10: 0
A11: 2 | B11: module-02-nen-tang-phat-am-chu-han | C11: 7 | D11: Chưa bắt đầu | E11: 0
A12: 3 | B12: module-03-hsk1-01-nhung-cau-dau-tien | C12: 2 | D12: Chưa bắt đầu | E12: 0
A13: 4 | B13: module-04-hsk1-02-lam-quen-va-gioi-thieu-ban-than | C13: 5 | D13: Chưa bắt đầu | E13: 0
A14: 5 | B14: module-05-hsk1-03-gioi-thieu-nguoi-xung-quanh | C14: 3 | D14: Chưa bắt đầu | E14: 0
A15: 6 | B15: module-06-hsk1-04-con-so-gia-dinh-tuoi-tac | C15: 7 | D15: Chưa bắt đầu | E15: 0
A16: 7 | B16: module-07-hsk1-05-kha-nang-va-mieu-ta | C16: 6 | D16: Chưa bắt đầu | E16: 0
A17: 8 | B17: module-08-hsk1-06-ngay-thang-va-di-chuyen | C17: 4 | D17: Chưa bắt đầu | E17: 0
A18: 9 | B18: module-09-hsk1-07-mong-muon-so-luong-tien-bac | C18: 6 | D18: Chưa bắt đầu | E18: 0
A19: 10 | B19: module-10-hsk1-08-dia-diem-va-nghe-nghiep | C19: 7 | D19: Chưa bắt đầu | E19: 0
A20: 11 | B20: module-11-hsk1-09-su-ton-tai-va-loi-de-nghi | C20: 4 | D20: Chưa bắt đầu | E20: 0
A21: 12 | B21: module-12-hsk1-10-gio-giac-va-lich-sinh-hoat | C21: 4 | D21: Chưa bắt đầu | E21: 0
... A65: 56 | B65: module-56-hoan-thanh-hanh-trinh-hsk | C65: 1 | D65: Chưa bắt đầu | E65: 0

Sheet C62 Khóa học Tiếng Trung — Giáo
A1: THEO DÕI KHÓA HỌC — Khóa học Tiếng Trung — Giáo trình Hán Ngữ Quyển 1–6
A2: Mã khóa | B2: C62 | C2: Lĩnh vực | D2: 06 - Ngôn ngữ | E2: Chuyên ngành | F2: 02 - Tiếng Trung
A3: Thư mục nguồn | B3: D:\Sao lưu\Udemy\Khóa học\06 - Ngôn ngữ\02 - Tiếng Trung\khoa-hoc-tieng-trung
A5: TỔNG MODULE | C5: ĐÃ HOÀN THÀNH | E5: TIẾN ĐỘ TRUNG BÌNH | G5: ĐIỂM TRUNG BÌNH
A6: =COUNTA(B10:B15) -> 6 | C6: =COUNTIF(D10:D15,"Đã hoàn thành") -> 0 | E6: =IFERROR(AVERAGE(E10:E15),0) -> 0 | G6: =IFERROR(AVERAGE(F10:F15),"")
A8: Nhập Trạng thái, Tiến độ và Điểm ở các ô nền vàng. Tiến độ nhập từ 0% đến 100%; điểm từ 0 đến 10.
A9: STT | B9: Module | C9: Số bài | D9: Trạng thái | E9: Tiến độ (%) | F9: Điểm /10 | G9: Ngày hoàn thành | H9: Ghi chú
A10: 1 | B10: module-01-quyen-1 | C10: 15 | D10: Chưa bắt đầu | E10: 0
A11: 2 | B11: module-02-quyen-2 | C11: 15 | D11: Chưa bắt đầu | E11: 0
A12: 3 | B12: module-03-quyen-3 | C12: 10 | D12: Chưa bắt đầu | E12: 0
A13: 4 | B13: module-04-quyen-4 | C13: 10 | D13: Chưa bắt đầu | E13: 0
A14: 5 | B14: module-05-quyen-5 | C14: 13 | D14: Chưa bắt đầu | E14: 0
A15: 6 | B15: module-06-quyen-6 | C15: 13 | D15: Chưa bắt đầu | E15: 0

Sheet C61 Từ vựng tiếng Anh cơ bản
A1: THEO DÕI KHÓA HỌC — Từ vựng tiếng Anh cơ bản
A2: Mã khóa | B2: C61 | C2: Lĩnh vực | D2: 06 - Ngôn ngữ | E2: Chuyên ngành | F2: 01 - Tiếng Anh
A3: Thư mục nguồn | B3: D:\Sao lưu\Udemy\Khóa học\06 - Ngôn ngữ\01 - Tiếng Anh\tu-vung-tieng-anh-co-ban
A5: TỔNG MODULE | C5: ĐÃ HOÀN THÀNH | E5: TIẾN ĐỘ TRUNG BÌNH | G5: ĐIỂM TRUNG BÌNH
A6: =COUNTA(B10:B10) -> 1 | C6: =COUNTIF(D10:D10,"Đã hoàn thành") -> 0 | E6: =IFERROR(AVERAGE(E10:E10),0) -> 0 | G6: =IFERROR(AVERAGE(F10:F10),"")
A8: Nhập Trạng thái, Tiến độ và Điểm ở các ô nền vàng. Tiến độ nhập từ 0% đến 100%; điểm từ 0 đến 10.
A9: STT | B9: Module | C9: Số bài | D9: Trạng thái | E9: Tiến độ (%) | F9: Điểm /10 | G9: Ngày hoàn thành | H9: Ghi chú
A10: 1 | B10: lessons | C10: 25 | D10: Chưa bắt đầu | E10: 0

Sheet C60 Tự học 2.000 từ vựng tiếng
A1: THEO DÕI KHÓA HỌC — Tự học 2.000 từ vựng tiếng Anh
A2: Mã khóa | B2: C60 | C2: Lĩnh vực | D2: 06 - Ngôn ngữ | E2: Chuyên ngành | F2: 01 - Tiếng Anh
A3: Thư mục nguồn | B3: D:\Sao lưu\Udemy\Khóa học\06 - Ngôn ngữ\01 - Tiếng Anh\tu-hoc-2000-tu-vung-tieng-anh
A5: TỔNG MODULE | C5: ĐÃ HOÀN THÀNH | E5: TIẾN ĐỘ TRUNG BÌNH | G5: ĐIỂM TRUNG BÌNH
A6: =COUNTA(B10:B15) -> 6 | C6: =COUNTIF(D10:D15,"Đã hoàn thành") -> 0 | E6: =IFERROR(AVERAGE(E10:E15),0) -> 0 | G6: =IFERROR(AVERAGE(F10:F15),"")
A8: Nhập Trạng thái, Tiến độ và Điểm ở các ô nền vàng. Tiến độ nhập từ 0% đến 100%; điểm từ 0 đến 10.
A9: STT | B9: Module | C9: Số bài | D9: Trạng thái | E9: Tiến độ (%) | F9: Điểm /10 | G9: Ngày hoàn thành | H9: Ghi chú
A10: 1 | B10: Module 01 - People and Body | C10: 8 | D10: Chưa bắt đầu | E10: 0
A11: 2 | B11: Module 02 - Family and Daily Life | C11: 8 | D11: Chưa bắt đầu | E11: 0
A12: 3 | B12: Module 03 - Home and Food | C12: 11 | D12: Chưa bắt đầu | E12: 0
A13: 4 | B13: Module 04 - Animals and Nature | C13: 3 | D13: Chưa bắt đầu | E13: 0
A14: 5 | B14: Module 05 - Hobbies and Travel | C14: 6 | D14: Chưa bắt đầu | E14: 0
A15: 6 | B15: Module 06 - Work and World | C15: 3 | D15: Chưa bắt đầu | E15: 0

Sheet C59 The English Master Course-
A1: THEO DÕI KHÓA HỌC — The English Master Course: English Grammar, English Speaking
A2: Mã khóa | B2: C59 | C2: Lĩnh vực | D2: 06 - Ngôn ngữ | E2: Chuyên ngành | F2: 01 - Tiếng Anh
A3: Thư mục nguồn | B3: D:\Sao lưu\Udemy\Khóa học\06 - Ngôn ngữ\01 - Tiếng Anh\the-english-master-course-english-grammar-speaking
A5: TỔNG MODULE | C5: ĐÃ HOÀN THÀNH | E5: TIẾN ĐỘ TRUNG BÌNH | G5: ĐIỂM TRUNG BÌNH
A6: =COUNTA(B10:B15) -> 6 | C6: =COUNTIF(D10:D15,"Đã hoàn thành") -> 0 | E6: =IFERROR(AVERAGE(E10:E15),0) -> 0 | G6: =IFERROR(AVERAGE(F10:F15),"")
A8: Nhập Trạng thái, Tiến độ và Điểm ở các ô nền vàng. Tiến độ nhập từ 0% đến 100%; điểm từ 0 đến 10.
A9: STT | B9: Module | C9: Số bài | D9: Trạng thái | E9: Tiến độ (%) | F9: Điểm /10 | G9: Ngày hoàn thành | H9: Ghi chú
A10: 1 | B10: 001 - How English Works - A Quick Review | C10: 8 | D10: Chưa bắt đầu | E10: 0
A11: 2 | B11: 002 - English Grammar | C11: 384 | D11: Chưa bắt đầu | E11: 0
A12: 3 | B12: 003 - English Writing | C12: 18 | D12: Chưa bắt đầu | E12: 0
A13: 4 | B13: 004 - English Speaking | C13: 22 | D13: Chưa bắt đầu | E13: 0
A14: 5 | B14: 005 - Pronunciation and Accent | C14: 49 | D14: Chưa bắt đầu | E14: 0
A15: 6 | B15: 006 - IELTS Upgrade and Practice | C15: 4 | D15: Chưa bắt đầu | E15: 0

Sheet C58 Pixel Art Master Course - B
A1: THEO DÕI KHÓA HỌC — Pixel Art Master Course - Beginner to Professional/Freelance
A2: Mã khóa | B2: C58 | C2: Lĩnh vực | D2: 05 - Phát triển game | E2: Chuyên ngành | F2: 05 - Game Art
A3: Thư mục nguồn | B3: D:\Sao lưu\Udemy\Khóa học\05 - Phát triển game\05 - Game Art\pixel-art-master-course-beginner-to-professional-freelance
A5: TỔNG MODULE | C5: ĐÃ HOÀN THÀNH | E5: TIẾN ĐỘ TRUNG BÌNH | G5: ĐIỂM TRUNG BÌNH
A6: =COUNTA(B10:B29) -> 20 | C6: =COUNTIF(D10:D29,"Đã hoàn thành") -> 0 | E6: =IFERROR(AVERAGE(E10:E29),0) -> 0 | G6: =IFERROR(AVERAGE(F10:F29),"")
A8: Nhập Trạng thái, Tiến độ và Điểm ở các ô nền vàng. Tiến độ nhập từ 0% đến 100%; điểm từ 0 đến 10.
A9: STT | B9: Module | C9: Số bài | D9: Trạng thái | E9: Tiến độ (%) | F9: Điểm /10 | G9: Ngày hoàn thành | H9: Ghi chú
A10: 1 | B10: 01 - Getting Started | C10: 8 | D10: Chưa bắt đầu | E10: 0
A11: 2 | B11: 02 - Lines and Shapes `[B]` | C11: 5 | D11: Chưa bắt đầu | E11: 0
A12: 3 | B12: 03 - Shading and Lighting `[B]` | C12: 12 | D12: Chưa bắt đầu | E12: 0
A13: 4 | B13: 04 - Colours and Textures `[B]` | C13: 11 | D13: Chưa bắt đầu | E13: 0
A14: 5 | B14: 05 - Drawing Simple Objects `[B]` | C14: 9 | D14: Chưa bắt đầu | E14: 0
A15: 6 | B15: 06 - Tiles `[B]` | C15: 8 | D15: Chưa bắt đầu | E15: 0
A16: 7 | B16: 07 - Backgrounds `[B]` | C16: 5 | D16: Chưa bắt đầu | E16: 0
A17: 8 | B17: 08 - Basic Characters `[B]` | C17: 5 | D17: Chưa bắt đầu | E17: 0
A18: 9 | B18: 09 - Simple Animation `[B]` | C18: 11 | D18: Chưa bắt đầu | E18: 0
A19: 10 | B19: 10 - Platformer View `[I]` | C19: 14 | D19: Chưa bắt đầu | E19: 0
A20: 11 | B20: 11 - Top Down View `[I]` | C20: 14 | D20: Chưa bắt đầu | E20: 0
A21: 12 | B21: 12 - RPG View `[I]` | C21: 12 | D21: Chưa bắt đầu | E21: 0
... A29: 20 | B29: 20 - Freelancing `[A]` | C29: 18 | D29: Chưa bắt đầu | E29: 0

Sheet C57 server-side-game-developer-
A1: THEO DÕI KHÓA HỌC — server-side-game-developer-roadmap
A2: Mã khóa | B2: C57 | C2: Lĩnh vực | D2: 05 - Phát triển game | E2: Chuyên ngành | F2: 04 - Game Development Roadmaps
A3: Thư mục nguồn | B3: D:\Sao lưu\Udemy\Khóa học\05 - Phát triển game\04 - Game Development Roadmaps\server-side-game-developer-roadmap
A5: TỔNG MODULE | C5: ĐÃ HOÀN THÀNH | E5: TIẾN ĐỘ TRUNG BÌNH | G5: ĐIỂM TRUNG BÌNH
A6: =COUNTA(B10:B10) -> 1 | C6: =COUNTIF(D10:D10,"Đã hoàn thành") -> 0 | E6: =IFERROR(AVERAGE(E10:E10),0) -> 0 | G6: =IFERROR(AVERAGE(F10:F10),"")
A8: Nhập Trạng thái, Tiến độ và Điểm ở các ô nền vàng. Tiến độ nhập từ 0% đến 100%; điểm từ 0 đến 10.
A9: STT | B9: Module | C9: Số bài | D9: Trạng thái | E9: Tiến độ (%) | F9: Điểm /10 | G9: Ngày hoàn thành | H9: Ghi chú
A10: 1 | B10: 00 - Roadmap.sh Server-Side Game Developer Official | C10: 79 | D10: Chưa bắt đầu | E10: 0

Sheet C56 game-developer-roadmap
A1: THEO DÕI KHÓA HỌC — game-developer-roadmap
A2: Mã khóa | B2: C56 | C2: Lĩnh vực | D2: 05 - Phát triển game | E2: Chuyên ngành | F2: 04 - Game Development Roadmaps
A3: Thư mục nguồn | B3: D:\Sao lưu\Udemy\Khóa học\05 - Phát triển game\04 - Game Development Roadmaps\game-developer-roadmap
A5: TỔNG MODULE | C5: ĐÃ HOÀN THÀNH | E5: TIẾN ĐỘ TRUNG BÌNH | G5: ĐIỂM TRUNG BÌNH
A6: =COUNTA(B10:B10) -> 1 | C6: =COUNTIF(D10:D10,"Đã hoàn thành") -> 0 | E6: =IFERROR(AVERAGE(E10:E10),0) -> 0 | G6: =IFERROR(AVERAGE(F10:F10),"")
A8: Nhập Trạng thái, Tiến độ và Điểm ở các ô nền vàng. Tiến độ nhập từ 0% đến 100%; điểm từ 0 đến 10.
A9: STT | B9: Module | C9: Số bài | D9: Trạng thái | E9: Tiến độ (%) | F9: Điểm /10 | G9: Ngày hoàn thành | H9: Ghi chú
A10: 1 | B10: 00 - Roadmap.sh Game Developer Official | C10: 32 | D10: Chưa bắt đầu | E10: 0

Sheet C55 Indie Game Design - Build Y
A1: THEO DÕI KHÓA HỌC — Indie Game Design - Build Your Game's Core System
A2: Mã khóa | B2: C55 | C2: Lĩnh vực | D2: 05 - Phát triển game | E2: Chuyên ngành | F2: 03 - Game Design
A3: Thư mục nguồn | B3: D:\Sao lưu\Udemy\Khóa học\05 - Phát triển game\03 - Game Design\indie-game-design-build-your-games-core-system
A5: TỔNG MODULE | C5: ĐÃ HOÀN THÀNH | E5: TIẾN ĐỘ TRUNG BÌNH | G5: ĐIỂM TRUNG BÌNH
A6: =COUNTA(B10:B17) -> 8 | C6: =COUNTIF(D10:D17,"Đã hoàn thành") -> 0 | E6: =IFERROR(AVERAGE(E10:E17),0) -> 0 | G6: =IFERROR(AVERAGE(F10:F17),"")
A8: Nhập Trạng thái, Tiến độ và Điểm ở các ô nền vàng. Tiến độ nhập từ 0% đến 100%; điểm từ 0 đến 10.
A9: STT | B9: Module | C9: Số bài | D9: Trạng thái | E9: Tiến độ (%) | F9: Điểm /10 | G9: Ngày hoàn thành | H9: Ghi chú
A10: 1 | B10: 01 - Introduction | C10: 2 | D10: Chưa bắt đầu | E10: 0
A11: 2 | B11: 02 - Understand How to Build a Core Gameplay | C11: 6 | D11: Chưa bắt đầu | E11: 0
A12: 3 | B12: 03 - Workshop - Define Your Game System, Part 1 | C12: 1 | D12: Chưa bắt đầu | E12: 0
A13: 4 | B13: 04 - Build Your Engagement Gameplay to Keep Your Players | C13: 7 | D13: Chưa bắt đầu | E13: 0
A14: 5 | B14: 05 - Workshop - Define Your Game System, Part 2 | C14: 1 | D14: Chưa bắt đầu | E14: 0
A15: 6 | B15: 06 - Design Support Features That Will Make Your Game Shine | C15: 5 | D15: Chưa bắt đầu | E15: 0
A16: 7 | B16: 07 - Workshop - Define Your Game System, Part 3 | C16: 1 | D16: Chưa bắt đầu | E16: 0
A17: 8 | B17: 08 - Conclusion | C17: 1 | D17: Chưa bắt đầu | E17: 0

Sheet C54 Ren'Py Minigames 101
A1: THEO DÕI KHÓA HỌC — Ren'Py Minigames 101
A2: Mã khóa | B2: C54 | C2: Lĩnh vực | D2: 05 - Phát triển game | E2: Chuyên ngành | F2: 02 - Ren'Py & Visual Novels
A3: Thư mục nguồn | B3: D:\Sao lưu\Udemy\Khóa học\05 - Phát triển game\02 - Ren'Py & Visual Novels\renpy-minigames-101
A5: TỔNG MODULE | C5: ĐÃ HOÀN THÀNH | E5: TIẾN ĐỘ TRUNG BÌNH | G5: ĐIỂM TRUNG BÌNH
A6: =COUNTA(B10:B13) -> 4 | C6: =COUNTIF(D10:D13,"Đã hoàn thành") -> 0 | E6: =IFERROR(AVERAGE(E10:E13),0) -> 0 | G6: =IFERROR(AVERAGE(F10:F13),"")
A8: Nhập Trạng thái, Tiến độ và Điểm ở các ô nền vàng. Tiến độ nhập từ 0% đến 100%; điểm từ 0 đến 10.
A9: STT | B9: Module | C9: Số bài | D9: Trạng thái | E9: Tiến độ (%) | F9: Điểm /10 | G9: Ngày hoàn thành | H9: Ghi chú
A10: 1 | B10: 01 - Introduction | C10: 3 | D10: Chưa bắt đầu | E10: 0
A11: 2 | B11: 02 - Rendering the Game View | C11: 6 | D11: Chưa bắt đầu | E11: 0
A12: 3 | B12: 03 - Detecting Player Interaction Events | C12: 3 | D12: Chưa bắt đầu | E12: 0
A13: 4 | B13: 04 - Bonus Features Course Recap and Conclusion | C13: 3 | D13: Chưa bắt đầu | E13: 0

Sheet C53 Python Basics for Ren'Py De
A1: THEO DÕI KHÓA HỌC — Python Basics for Ren'Py Developers
A2: Mã khóa | B2: C53 | C2: Lĩnh vực | D2: 05 - Phát triển game | E2: Chuyên ngành | F2: 02 - Ren'Py & Visual Novels
A3: Thư mục nguồn | B3: D:\Sao lưu\Udemy\Khóa học\05 - Phát triển game\02 - Ren'Py & Visual Novels\python-basics-for-renpy-developers
A5: TỔNG MODULE | C5: ĐÃ HOÀN THÀNH | E5: TIẾN ĐỘ TRUNG BÌNH | G5: ĐIỂM TRUNG BÌNH
A6: =COUNTA(B10:B15) -> 6 | C6: =COUNTIF(D10:D15,"Đã hoàn thành") -> 0 | E6: =IFERROR(AVERAGE(E10:E15),0) -> 0 | G6: =IFERROR(AVERAGE(F10:F15),"")
A8: Nhập Trạng thái, Tiến độ và Điểm ở các ô nền vàng. Tiến độ nhập từ 0% đến 100%; điểm từ 0 đến 10.
A9: STT | B9: Module | C9: Số bài | D9: Trạng thái | E9: Tiến độ (%) | F9: Điểm /10 | G9: Ngày hoàn thành | H9: Ghi chú
A10: 1 | B10: 01 - Introduction | C10: 2 | D10: Chưa bắt đầu | E10: 0
A11: 2 | B11: 02 - Variables in Python | C11: 3 | D11: Chưa bắt đầu | E11: 0
A12: 3 | B12: 03 - Data Structures in Python | C12: 3 | D12: Chưa bắt đầu | E12: 0
A13: 4 | B13: 04 - Python Statements | C13: 3 | D13: Chưa bắt đầu | E13: 0
A14: 5 | B14: 05 - Advanced Topics Functions and Classes | C14: 2 | D14: Chưa bắt đầu | E14: 0
A15: 6 | B15: 06 - Python Resources | C15: 1 | D15: Chưa bắt đầu | E15: 0

Sheet C52 Mastering Ren'Py- Create Vi
A1: THEO DÕI KHÓA HỌC — Mastering Ren'Py: Create Visual Novels Like a Pro
A2: Mã khóa | B2: C52 | C2: Lĩnh vực | D2: 05 - Phát triển game | E2: Chuyên ngành | F2: 02 - Ren'Py & Visual Novels
A3: Thư mục nguồn | B3: D:\Sao lưu\Udemy\Khóa học\05 - Phát triển game\02 - Ren'Py & Visual Novels\mastering-renpy-create-visual-novels-like-a-pro
A5: TỔNG MODULE | C5: ĐÃ HOÀN THÀNH | E5: TIẾN ĐỘ TRUNG BÌNH | G5: ĐIỂM TRUNG BÌNH
A6: =COUNTA(B10:B11) -> 2 | C6: =COUNTIF(D10:D11,"Đã hoàn thành") -> 0 | E6: =IFERROR(AVERAGE(E10:E11),0) -> 0 | G6: =IFERROR(AVERAGE(F10:F11),"")
A8: Nhập Trạng thái, Tiến độ và Điểm ở các ô nền vàng. Tiến độ nhập từ 0% đến 100%; điểm từ 0 đến 10.
A9: STT | B9: Module | C9: Số bài | D9: Trạng thái | E9: Tiến độ (%) | F9: Điểm /10 | G9: Ngày hoàn thành | H9: Ghi chú
A10: 1 | B10: 01 - Installation and Interface of RenPy | C10: 4 | D10: Chưa bắt đầu | E10: 0
A11: 2 | B11: 02 - Creating Your First Game | C11: 11 | D11: Chưa bắt đầu | E11: 0

Sheet C51 Complete C# Unity 3D Game D
A1: THEO DÕI KHÓA HỌC — Complete C# Unity 3D Game Development in Unity 6
A2: Mã khóa | B2: C51 | C2: Lĩnh vực | D2: 05 - Phát triển game | E2: Chuyên ngành | F2: 01 - Unity & C#
A3: Thư mục nguồn | B3: D:\Sao lưu\Udemy\Khóa học\05 - Phát triển game\01 - Unity & C#\complete-csharp-unity-3d-game-development-unity-6
A5: TỔNG MODULE | C5: ĐÃ HOÀN THÀNH | E5: TIẾN ĐỘ TRUNG BÌNH | G5: ĐIỂM TRUNG BÌNH
A6: =COUNTA(B10:B16) -> 7 | C6: =COUNTIF(D10:D16,"Đã hoàn thành") -> 0 | E6: =IFERROR(AVERAGE(E10:E16),0) -> 0 | G6: =IFERROR(AVERAGE(F10:F16),"")
A8: Nhập Trạng thái, Tiến độ và Điểm ở các ô nền vàng. Tiến độ nhập từ 0% đến 100%; điểm từ 0 đến 10.
A9: STT | B9: Module | C9: Số bài | D9: Trạng thái | E9: Tiến độ (%) | F9: Điểm /10 | G9: Ngày hoàn thành | H9: Ghi chú
A10: 1 | B10: 01 - Introduction and Setup | C10: 8 | D10: Chưa bắt đầu | E10: 0
A11: 2 | B11: 02 - Obstacle Dodge | C11: 27 | D11: Chưa bắt đầu | E11: 0
A12: 3 | B12: 03 - Rocket Boost | C12: 34 | D12: Chưa bắt đầu | E12: 0
A13: 4 | B13: 04 - Galaxy Strike | C13: 41 | D13: Chưa bắt đầu | E13: 0
A14: 5 | B14: 05 - Royal Run | C14: 38 | D14: Chưa bắt đầu | E14: 0
A15: 6 | B15: 06 - Sharp Shooter | C15: 43 | D15: Chưa bắt đầu | E15: 0
A16: 7 | B16: 07 - Bonus- One Last Thing | C16: 1 | D16: Chưa bắt đầu | E16: 0

Sheet C50 Complete C# Unity 2D Game D
A1: THEO DÕI KHÓA HỌC — Complete C# Unity 2D Game Development - Updated To Unity 6
A2: Mã khóa | B2: C50 | C2: Lĩnh vực | D2: 05 - Phát triển game | E2: Chuyên ngành | F2: 01 - Unity & C#
A3: Thư mục nguồn | B3: D:\Sao lưu\Udemy\Khóa học\05 - Phát triển game\01 - Unity & C#\complete-csharp-unity-2d-game-development-unity-6
A5: TỔNG MODULE | C5: ĐÃ HOÀN THÀNH | E5: TIẾN ĐỘ TRUNG BÌNH | G5: ĐIỂM TRUNG BÌNH
A6: =COUNTA(B10:B15) -> 6 | C6: =COUNTIF(D10:D15,"Đã hoàn thành") -> 0 | E6: =IFERROR(AVERAGE(E10:E15),0) -> 0 | G6: =IFERROR(AVERAGE(F10:F15),"")
A8: Nhập Trạng thái, Tiến độ và Điểm ở các ô nền vàng. Tiến độ nhập từ 0% đến 100%; điểm từ 0 đến 10.
A9: STT | B9: Module | C9: Số bài | D9: Trạng thái | E9: Tiến độ (%) | F9: Điểm /10 | G9: Ngày hoàn thành | H9: Ghi chú
A10: 1 | B10: 01 - Introduction and Setup | C10: 6 | D10: Chưa bắt đầu | E10: 0
A11: 2 | B11: 02 - Delivery Dash | C11: 24 | D11: Chưa bắt đầu | E11: 0
A12: 3 | B12: 03 - Snow Surfer | C12: 29 | D12: Chưa bắt đầu | E12: 0
A13: 4 | B13: 04 - Tilemania | C13: 41 | D13: Chưa bắt đầu | E13: 0
A14: 5 | B14: 05 - Star Blaster | C14: 30 | D14: Chưa bắt đầu | E14: 0
A15: 6 | B15: 06 - Bonus One Last Thing | C15: 2 | D15: Chưa bắt đầu | E15: 0

Sheet C49 05 - Cơ học & thủy động lực
A1: THEO DÕI KHÓA HỌC — 05 - Cơ học & thủy động lực học bơi cá
A2: Mã khóa | B2: C49 | C2: Lĩnh vực | D2: 04 - Thiết kế & Sáng tạo số | E2: Chuyên ngành | F2: 03 - Blender & 3D
A3: Thư mục nguồn | B3: D:\Sao lưu\Udemy\Khóa học\04 - Thiết kế & Sáng tạo số\03 - Blender & 3D\05 - Cơ học & thủy động lực học bơi cá
A5: TỔNG MODULE | C5: ĐÃ HOÀN THÀNH | E5: TIẾN ĐỘ TRUNG BÌNH | G5: ĐIỂM TRUNG BÌNH
A6: =COUNTA(B10:B28) -> 19 | C6: =COUNTIF(D10:D28,"Đã hoàn thành") -> 0 | E6: =IFERROR(AVERAGE(E10:E28),0) -> 0 | G6: =IFERROR(AVERAGE(F10:F28),"")
A8: Nhập Trạng thái, Tiến độ và Điểm ở các ô nền vàng. Tiến độ nhập từ 0% đến 100%; điểm từ 0 đến 10.
A9: STT | B9: Module | C9: Số bài | D9: Trạng thái | E9: Tiến độ (%) | F9: Điểm /10 | G9: Ngày hoàn thành | H9: Ghi chú
A10: 1 | B10: hydrodynamics-of-fishlike-swimming — 01-nen-tang | C10: 1 | D10: Chưa bắt đầu | E10: 0
A11: 2 | B11: hydrodynamics-of-fishlike-swimming — 02-canh-dao-dong | C11: 2 | D11: Chưa bắt đầu | E11: 0
A12: 3 | B12: hydrodynamics-of-fishlike-swimming — 03-boi-on-dinh | C12: 2 | D12: Chưa bắt đầu | E12: 0
A13: 4 | B13: hydrodynamics-of-fishlike-swimming — 04-co-dong | C13: 1 | D13: Chưa bắt đầu | E13: 0
A14: 5 | B14: hydrodynamics-of-fishlike-swimming — 05-biomimetic | C14: 2 | D14: Chưa bắt đầu | E14: 0
A15: 6 | B15: hydrodynamics-of-fishlike-swimming — 06-on-tap | C15: 2 | D15: Chưa bắt đầu | E15: 0
A16: 7 | B16: hydrodynamics-of-fishlike-swimming — 07-phu-luc | C16: 3 | D16: Chưa bắt đầu | E16: 0
A17: 8 | B17: lauder-tytell-2006-hydrodynamics — 01 - Propulsion Foundations | C17: 4 | D17: Chưa bắt đầu | E17: 0
A18: 9 | B18: lauder-tytell-2006-hydrodynamics — 02 - Mathematical Models | C18: 2 | D18: Chưa bắt đầu | E18: 0
A19: 10 | B19: lauder-tytell-2006-hydrodynamics — 03 - Experimental Methods and Wakes | C19: 4 | D19: Chưa bắt đầu | E19: 0
A20: 11 | B20: lauder-tytell-2006-hydrodynamics — 04 - Whole-body Hydrodynamics and Turbulence | C20: 3 | D20: Chưa bắt đầu | E20: 0
A21: 12 | B21: lauder-tytell-2006-hydrodynamics — 05 - Theory, Evidence, and Future Work | C21: 3 | D21: Chưa bắt đầu | E21: 0
... A28: 19 | B28: review-of-fish-swimming-modes — 06 - References and Study Tools | C28: 4 | D28: Chưa bắt đầu | E28: 0

Sheet C48 04 - Giải phẫu & phát triển
A1: THEO DÕI KHÓA HỌC — 04 - Giải phẫu & phát triển bộ xương cá
A2: Mã khóa | B2: C48 | C2: Lĩnh vực | D2: 04 - Thiết kế & Sáng tạo số | E2: Chuyên ngành | F2: 03 - Blender & 3D
A3: Thư mục nguồn | B3: D:\Sao lưu\Udemy\Khóa học\04 - Thiết kế & Sáng tạo số\03 - Blender & 3D\04 - Giải phẫu & phát triển bộ xương cá
A5: TỔNG MODULE | C5: ĐÃ HOÀN THÀNH | E5: TIẾN ĐỘ TRUNG BÌNH | G5: ĐIỂM TRUNG BÌNH
A6: =COUNTA(B10:B21) -> 12 | C6: =COUNTIF(D10:D21,"Đã hoàn thành") -> 0 | E6: =IFERROR(AVERAGE(E10:E21),0) -> 0 | G6: =IFERROR(AVERAGE(F10:F21),"")
A8: Nhập Trạng thái, Tiến độ và Điểm ở các ô nền vàng. Tiến độ nhập từ 0% đến 100%; điểm từ 0 đến 10.
A9: STT | B9: Module | C9: Số bài | D9: Trạng thái | E9: Tiến độ (%) | F9: Điểm /10 | G9: Ngày hoàn thành | H9: Ghi chú
A10: 1 | B10: astatotilapia-burtoni-skeletal-ontogeny — 01 - Foundations and Study Guide | C10: 3 | D10: Chưa bắt đầu | E10: 0
A11: 2 | B11: astatotilapia-burtoni-skeletal-ontogeny — 02 - Embryonic Development | C11: 2 | D11: Chưa bắt đầu | E11: 0
A12: 3 | B12: astatotilapia-burtoni-skeletal-ontogeny — 03 - Axial and Median Fins | C12: 3 | D12: Chưa bắt đầu | E12: 0
A13: 4 | B13: astatotilapia-burtoni-skeletal-ontogeny — 04 - Paired Fins | C13: 3 | D13: Chưa bắt đầu | E13: 0
A14: 5 | B14: astatotilapia-burtoni-skeletal-ontogeny — 05 - Caudal, Scales, and Cranium | C14: 3 | D14: Chưa bắt đầu | E14: 0
A15: 6 | B15: astatotilapia-burtoni-skeletal-ontogeny — 06 - Methods and Evo-Devo | C15: 4 | D15: Chưa bắt đầu | E15: 0
A16: 7 | B16: astatotilapia-burtoni-skeletal-ontogeny — 07 - Figures and Study Tools | C16: 4 | D16: Chưa bắt đầu | E16: 0
A17: 8 | B17: astatotilapia-burtoni-skeletal-ontogeny — 03 - Axial and Median Fins | C17: 0 | D17: Chưa bắt đầu | E17: 0
A18: 9 | B18: astatotilapia-burtoni-skeletal-ontogeny — 06 - Methods and Evo-Devo | C18: 0 | D18: Chưa bắt đầu | E18: 0
A19: 10 | B19: astatotilapia-burtoni-skeletal-ontogeny — 07 - Figures and Study Tools | C19: 0 | D19: Chưa bắt đầu | E19: 0
A20: 11 | B20: astatotilia-burtoni-skeletal-ontogeny — 03 - Axial and Median Fins | C20: 0 | D20: Chưa bắt đầu | E20: 0
A21: 12 | B21: astatotilia-burtoni-skeletal-ontogeny — 07 - Figures and Study Tools | C21: 0 | D21: Chưa bắt đầu | E21: 0

Sheet C47 03 - VFX & mô phỏng Blender
A1: THEO DÕI KHÓA HỌC — 03 - VFX & mô phỏng Blender
A2: Mã khóa | B2: C47 | C2: Lĩnh vực | D2: 04 - Thiết kế & Sáng tạo số | E2: Chuyên ngành | F2: 03 - Blender & 3D
A3: Thư mục nguồn | B3: D:\Sao lưu\Udemy\Khóa học\04 - Thiết kế & Sáng tạo số\03 - Blender & 3D\03 - VFX & mô phỏng Blender
A5: TỔNG MODULE | C5: ĐÃ HOÀN THÀNH | E5: TIẾN ĐỘ TRUNG BÌNH | G5: ĐIỂM TRUNG BÌNH
A6: =COUNTA(B10:B13) -> 4 | C6: =COUNTIF(D10:D13,"Đã hoàn thành") -> 0 | E6: =IFERROR(AVERAGE(E10:E13),0) -> 0 | G6: =IFERROR(AVERAGE(F10:F13),"")
A8: Nhập Trạng thái, Tiến độ và Điểm ở các ô nền vàng. Tiến độ nhập từ 0% đến 100%; điểm từ 0 đến 10.
A9: STT | B9: Module | C9: Số bài | D9: Trạng thái | E9: Tiến độ (%) | F9: Điểm /10 | G9: Ngày hoàn thành | H9: Ghi chú
A10: 1 | B10: blender-2-8-tutorial-cell-fracture-explosion | C10: 1 | D10: Chưa bắt đầu | E10: 0
A11: 2 | B11: blender-tutorial-quick-explosion-simulation-with-mantaflow-in-cycles | C11: 1 | D11: Chưa bắt đầu | E11: 0
A12: 3 | B12: blender-tutorial-surface-cracks | C12: 1 | D12: Chưa bắt đầu | E12: 0
A13: 4 | B13: how-to-create-glowing-surface-cracks-blender-tutorial | C13: 1 | D13: Chưa bắt đầu | E13: 0

Sheet C46 02 - Animation cá trong Ble
A1: THEO DÕI KHÓA HỌC — 02 - Animation cá trong Blender
A2: Mã khóa | B2: C46 | C2: Lĩnh vực | D2: 04 - Thiết kế & Sáng tạo số | E2: Chuyên ngành | F2: 03 - Blender & 3D
A3: Thư mục nguồn | B3: D:\Sao lưu\Udemy\Khóa học\04 - Thiết kế & Sáng tạo số\03 - Blender & 3D\02 - Animation cá trong Blender
A5: TỔNG MODULE | C5: ĐÃ HOÀN THÀNH | E5: TIẾN ĐỘ TRUNG BÌNH | G5: ĐIỂM TRUNG BÌNH
A6: =COUNTA(B10:B13) -> 4 | C6: =COUNTIF(D10:D13,"Đã hoàn thành") -> 0 | E6: =IFERROR(AVERAGE(E10:E13),0) -> 0 | G6: =IFERROR(AVERAGE(F10:F13),"")
A8: Nhập Trạng thái, Tiến độ và Điểm ở các ô nền vàng. Tiến độ nhập từ 0% đến 100%; điểm từ 0 đến 10.
A9: STT | B9: Module | C9: Số bài | D9: Trạng thái | E9: Tiến độ (%) | F9: Điểm /10 | G9: Ngày hoàn thành | H9: Ghi chú
A10: 1 | B10: animate-and-render-a-fish-in-blender | C10: 11 | D10: Chưa bắt đầu | E10: 0
A11: 2 | B11: blender-2-8-particle-school-of-fish-following-a-leader | C11: 8 | D11: Chưa bắt đầu | E11: 0
A12: 3 | B12: creating-an-animated-school-of-fish-in-blender | C12: 12 | D12: Chưa bắt đầu | E12: 0
A13: 4 | B13: the-secret-to-easy-fish-animation-in-blender | C13: 9 | D13: Chưa bắt đầu | E13: 0

Sheet C45 01 - Blender tổng quát
A1: THEO DÕI KHÓA HỌC — 01 - Blender tổng quát
A2: Mã khóa | B2: C45 | C2: Lĩnh vực | D2: 04 - Thiết kế & Sáng tạo số | E2: Chuyên ngành | F2: 03 - Blender & 3D
A3: Thư mục nguồn | B3: D:\Sao lưu\Udemy\Khóa học\04 - Thiết kế & Sáng tạo số\03 - Blender & 3D\01 - Blender tổng quát
